Workbook
Name Slicer_Channel: #N/A
Name Slicer_Region: #N/A

Sheet campaign_data
A1: Campaign Name | B1: Channel | C1: Region | D1: Start Date | E1: End Date | F1: Spend | G1: Impressions | H1: Clicks | I1: Leads | J1: Conversions | K1: Revenue | L1: CTR (Click-Through Rate) | M1: LEAD CONVERSION RATE | N1: CONVERSION RATE | O1: CPL (Cost Per Lead) | P1: CPA (Cost Per Acquisition) | Q1: ROI % (Return on Investment) | R1: Profit
A2: Q1 Email Blast | B2: Email | C2: North America | D2: 45292 | E2: 45326 | F2: 1472 | G2: 12064 | H2: 2741 | I2: 368 | J2: 41 | K2: 6400 | L2: =campaign_data[[#This Row],[Clicks]]/campaign_data[[#This Row],[Impressions]] -> 0.22720491 | M2: =campaign_data[[#This Row],[Leads]]/campaign_data[[#This Row],[Clicks]] -> 0.13425757 | N2: =campaign_data[[#This Row],[Conversions]]/campaign_data[[#This Row],[Leads]] -> 0.11141304 | O2: =campaign_data[[#This Row],[Spend]]/campaign_data[[#This Row],[Leads]] -> 4 | P2: =IF(campaign_data[[#This Row],[Conversions]] > 0, campaign_data[[#This Row],[Spend]]/campaign_data[[#This Row],[Conversions]], 0) -> 35.902439 | Q2: =IF(campaign_data[[#This Row],[Spend]]>0, (campaign_data[[#This Row],[Revenue]]-campaign_data[[#This Row],[Spend]])/campaign_data[[#This Row],[Spend]],0) -> 3.3478261 | R2: =campaign_data[[#This Row],[Revenue]]-campaign_data[[#This Row],[Spend]] -> 4928
A3: Spring Social Push | B3: Social | C3: Europe | D3: 45297 | E3: 45329 | F3: 4240 | G3: 38091 | H3: 3238 | I3: 269 | J3: 13 | K3: 6324 | L3: =campaign_data[[#This Row],[Clicks]]/campaign_data[[#This Row],[Impressions]] -> 0.085006957 | M3: =campaign_data[[#This Row],[Leads]]/campaign_data[[#This Row],[Clicks]] -> 0.083075973 | N3: =campaign_data[[#This Row],[Conversions]]/campaign_data[[#This Row],[Leads]] -> 0.048327138 | O3: =campaign_data[[#This Row],[Spend]]/campaign_data[[#This Row],[Leads]] -> 15.762082 | P3: =IF(campaign_data[[#This Row],[Conversions]] > 0, campaign_data[[#This Row],[Spend]]/campaign_data[[#This Row],[Conversions]], 0) -> 326.15385 | Q3: =IF(campaign_data[[#This Row],[Spend]]>0, (campaign_data[[#This Row],[Revenue]]-campaign_data[[#This Row],[Spend]])/campaign_data[[#This Row],[Spend]],0) -> 0.49150943 | R3: =campaign_data[[#This Row],[Revenue]]-campaign_data[[#This Row],[Spend]] -> 2084
A4: Google Ads - Brand | B4: Paid Ads | C4: Asia Pacific | D4: 45303 | E4: 45328 | F4: 6088 | G4: 191467 | H4: 4661 | I4: 588 | J4: 25 | K4: 7538 | L4: =campaign_data[[#This Row],[Clicks]]/campaign_data[[#This Row],[Impressions]] -> 0.024343621 | M4: =campaign_data[[#This Row],[Leads]]/campaign_data[[#This Row],[Clicks]] -> 0.12615319 | N4: =campaign_data[[#This Row],[Conversions]]/campaign_data[[#This Row],[Leads]] -> 0.042517007 | O4: =campaign_data[[#This Row],[Spend]]/campaign_data[[#This Row],[Leads]] -> 10.353741 | P4: =IF(campaign_data[[#This Row],[Conversions]] > 0, campaign_data[[#This Row],[Spend]]/campaign_data[[#This Row],[Conversions]], 0) -> 243.52 | Q4: =IF(campaign_data[[#This Row],[Spend]]>0, (campaign_data[[#This Row],[Revenue]]-campaign_data[[#This Row],[Spend]])/campaign_data[[#This Row],[Spend]],0) -> 0.23817346 | R4: =campaign_data[[#This Row],[Revenue]]-campaign_data[[#This Row],[Spend]] -> 1450
A5: Facebook Retargeting | B5: Social | C5: Latin America | D5: 45308 | E5: 45333 | F5: 1710 | G5: 76568 | H5: 6706 | I5: 684 | J5: 40 | K5: 17537 | L5: =campaign_data[[#This Row],[Clicks]]/campaign_data[[#This Row],[Impressions]] -> 0.08758228 | M5: =campaign_data[[#This Row],[Leads]]/campaign_data[[#This Row],[Clicks]] -> 0.10199821 | N5: =campaign_data[[#This Row],[Conversions]]/campaign_data[[#This Row],[Leads]] -> 0.058479532 | O5: =campaign_data[[#This Row],[Spend]]/campaign_data[[#This Row],[Leads]] -> 2.5 | P5: =IF(campaign_data[[#This Row],[Conversions]] > 0, campaign_data[[#This Row],[Spend]]/campaign_data[[#This Row],[Conversions]], 0) -> 42.75 | Q5: =IF(campaign_data[[#This Row],[Spend]]>0, (campaign_data[[#This Row],[Revenue]]-campaign_data[[#This Row],[Spend]])/campaign_data[[#This Row],[Spend]],0) -> 9.2555556 | R5: =campaign_data[[#This Row],[Revenue]]-campaign_data[[#This Row],[Spend]] -> 15827
A6: LinkedIn B2B Campaign | B6: Social | C6: North America | D6: 45314 | E6: 45344 | F6: 4435 | G6: 57116 | H6: 3593 | I6: 340 | J6: 36 | K6: 11622 | L6: =campaign_data[[#This Row],[Clicks]]/campaign_data[[#This Row],[Impressions]] -> 0.062907066 | M6: =campaign_data[[#This Row],[Leads]]/campaign_data[[#This Row],[Clicks]] -> 0.094628444 | N6: =campaign_data[[#This Row],[Conversions]]/campaign_data[[#This Row],[Leads]] -> 0.10588235 | O6: =campaign_data[[#This Row],[Spend]]/campaign_data[[#This Row],[Leads]] -> 13.044118 | P6: =IF(campaign_data[[#This Row],[Conversions]] > 0, campaign_data[[#This Row],[Spend]]/campaign_data[[#This Row],[Conversions]], 0) -> 123.19444 | Q6: =IF(campaign_data[[#This Row],[Spend]]>0, (campaign_data[[#This Row],[Revenue]]-campaign_data[[#This Row],[Spend]])/campaign_data[[#This Row],[Spend]],0) -> 1.6205186 | R6: =campaign_data[[#This Row],[Revenue]]-campaign_data[[#This Row],[Spend]] -> 7187
A7: Instagram Influencer | B7: Social | C7: Europe | D7: 45319 | E7: 45355 | F7: 4477 | G7: 38111 | H7: 10045 | I7: 1100 | J7: 126 | K7: 38341 | L7: =campaign_data[[#This Row],[Clicks]]/campaign_data[[#This Row],[Impressions]] -> 0.2635722 | M7: =campaign_data[[#This Row],[Leads]]/campaign_data[[#This Row],[Clicks]] -> 0.10950722 | N7: =campaign_data[[#This Row],[Conversions]]/campaign_data[[#This Row],[Leads]] -> 0.11454545 | O7: =campaign_data[[#This Row],[Spend]]/campaign_data[[#This Row],[Leads]] -> 4.07 | P7: =IF(campaign_data[[#This Row],[Conversions]] > 0, campaign_data[[#This Row],[Spend]]/campaign_data[[#This Row],[Conversions]], 0) -> 35.531746 | Q7: =IF(campaign_data[[#This Row],[Spend]]>0, (campaign_data[[#This Row],[Revenue]]-campaign_data[[#This Row],[Spend]])/campaign_data[[#This Row],[Spend]],0) -> 7.5639937 | R7: =campaign_data[[#This Row],[Revenue]]-campaign_data[[#This Row],[Spend]] -> 33864
A8: Email Newsletter | B8: Email | C8: Asia Pacific | D8: 45325 | E8: 45358 | F8: 689 | G8: 14303 | H8: 3512 | I8: 533 | J8: 62 | K8: 24389 | L8: =campaign_data[[#This Row],[Clicks]]/campaign_data[[#This Row],[Impressions]] -> 0.24554289 | M8: =campaign_data[[#This Row],[Leads]]/campaign_data[[#This Row],[Clicks]] -> 0.15176538 | N8: =campaign_data[[#This Row],[Conversions]]/campaign_data[[#This Row],[Leads]] -> 0.1163227 | O8: =campaign_data[[#This Row],[Spend]]/campaign_data[[#This Row],[Leads]] -> 1.2926829 | P8: =IF(campaign_data[[#This Row],[Conversions]] > 0, campaign_data[[#This Row],[Spend]]/campaign_data[[#This Row],[Conversions]], 0) -> 11.112903 | Q8: =IF(campaign_data[[#This Row],[Spend]]>0, (campaign_data[[#This Row],[Revenue]]-campaign_data[[#This Row],[Spend]])/campaign_data[[#This Row],[Spend]],0) -> 34.397678 | R8: =campaign_data[[#This Row],[Revenue]]-campaign_data[[#This Row],[Spend]] -> 23700
A9: YouTube Pre-roll | B9: Social | C9: Latin America | D9: 45330 | E9: 45358 | F9: 4208 | G9: 70611 | H9: 6044 | I9: 539 | J9: 46 | K9: 11047 | L9: =campaign_data[[#This Row],[Clicks]]/campaign_data[[#This Row],[Impressions]] -> 0.085595729 | M9: =campaign_data[[#This Row],[Leads]]/campaign_data[[#This Row],[Clicks]] -> 0.089179351 | N9: =campaign_data[[#This Row],[Conversions]]/campaign_data[[#This Row],[Leads]] -> 0.085343228 | O9: =campaign_data[[#This Row],[Spend]]/campaign_data[[#This Row],[Leads]] -> 7.8070501 | P9: =IF(campaign_data[[#This Row],[Conversions]] > 0, campaign_data[[#This Row],[Spend]]/campaign_data[[#This Row],[Conversions]], 0) -> 91.478261 | Q9: =IF(campaign_data[[#This Row],[Spend]]>0, (campaign_data[[#This Row],[Revenue]]-campaign_data[[#This Row],[Spend]])/campaign_data[[#This Row],[Spend]],0) -> 1.6252376 | R9: =campaign_data[[#This Row],[Revenue]]-campaign_data[[#This Row],[Spend]] -> 6839
A10: Twitter Engagement | B10: Social | C10: North America | D10: 45336 | E10: 45373 | F10: 2208 | G10: 23816 | H10: 2196 | I10: 199 | J10: 18 | K10: 5234 | L10: =campaign_data[[#This Row],[Clicks]]/campaign_data[[#This Row],[Impressions]] -> 0.09220692 | M10: =campaign_data[[#This Row],[Leads]]/campaign_data[[#This Row],[Clicks]] -> 0.090619308 | N10: =campaign_data[[#This Row],[Conversions]]/campaign_data[[#This Row],[Leads]] -> 0.090452261 | O10: =campaign_data[[#This Row],[Spend]]/campaign_data[[#This Row],[Leads]] -> 11.095477 | P10: =IF(campaign_data[[#This Row],[Conversions]] > 0, campaign_data[[#This Row],[Spend]]/campaign_data[[#This Row],[Conversions]], 0) -> 122.66667 | Q10: =IF(campaign_data[[#This Row],[Spend]]>0, (campaign_data[[#This Row],[Revenue]]-campaign_data[[#This Row],[Spend]])/campaign_data[[#This Row],[Spend]],0) -> 1.370471 | R10: =campaign_data[[#This Row],[Revenue]]-campaign_data[[#This Row],[Spend]] -> 3026
A11: Google Ads - Product | B11: Paid Ads | C11: Europe | D11: 45341 | E11: 45383 | F11: 2861 | G11: 208334 | H11: 9358 | I11: 858 | J11: 78 | K11: 22529 | L11: =campaign_data[[#This Row],[Clicks]]/campaign_data[[#This Row],[Impressions]] -> 0.044918256 | M11: =campaign_data[[#This Row],[Leads]]/campaign_data[[#This Row],[Clicks]] -> 0.091686258 | N11: =campaign_data[[#This Row],[Conversions]]/campaign_data[[#This Row],[Leads]] -> 0.090909091 | O11: =campaign_data[[#This Row],[Spend]]/campaign_data[[#This Row],[Leads]] -> 3.3344988 | P11: =IF(campaign_data[[#This Row],[Conversions]] > 0, campaign_data[[#This Row],[Spend]]/campaign_data[[#This Row],[Conversions]], 0) -> 36.679487 | Q11: =IF(campaign_data[[#This Row],[Spend]]>0, (campaign_data[[#This Row],[Revenue]]-campaign_data[[#This Row],[Spend]])/campaign_data[[#This Row],[Spend]],0) -> 6.8745194 | R11: =campaign_data[[#This Row],[Revenue]]-campaign_data[[#This Row],[Spend]] -> 19668
A12: Email Promo | B12: Email | C12: Asia Pacific | D12: 45347 | E12: 45370 | F12: 1907 | G12: 13227 | H12: 2411 | I12: 424 | J12: 49 | K12: 22684 | L12: =campaign_data[[#This Row],[Clicks]]/campaign_data[[#This Row],[Impressions]] -> 0.18227867 | M12: =campaign_data[[#This Row],[Leads]]/campaign_data[[#This Row],[Clicks]] -> 0.17586064 | N12: =campaign_data[[#This Row],[Conversions]]/campaign_data[[#This Row],[Leads]] -> 0.11556604 | O12: =campaign_data[[#This Row],[Spend]]/campaign_data[[#This Row],[Leads]] -> 4.4976415 | P12: =IF(campaign_data[[#This Row],[Conversions]] > 0, campaign_data[[#This Row],[Spend]]/campaign_data[[#This Row],[Conversions]], 0) -> 38.918367 | Q12: =IF(campaign_data[[#This Row],[Spend]]>0, (campaign_data[[#This Row],[Revenue]]-campaign_data[[#This Row],[Spend]])/campaign_data[[#This Row],[Spend]],0) -> 10.895123 | R12: =campaign_data[[#This Row],[Revenue]]-campaign_data[[#This Row],[Spend]] -> 20777
A13: TikTok Brand Awareness | B13: Social | C13: Latin America | D13: 45352 | E13: 45387 | F13: 1313 | G13: 37132 | H13: 3364 | I13: 443 | J13: 31 | K13: 9969 | L13: =campaign_data[[#This Row],[Clicks]]/campaign_data[[#This Row],[Impressions]] -> 0.090595713 | M13: =campaign_data[[#This Row],[Leads]]/campaign_data[[#This Row],[Clicks]] -> 0.13168847 | N13: =campaign_data[[#This Row],[Conversions]]/campaign_data[[#This Row],[Leads]] -> 0.069977427 | O13: =campaign_data[[#This Row],[Spend]]/campaign_data[[#This Row],[Leads]] -> 2.9638826 | P13: =IF(campaign_data[[#This Row],[Conversions]] > 0, campaign_data[[#This Row],[Spend]]/campaign_data[[#This Row],[Conversions]], 0) -> 42.354839 | Q13: =IF(campaign_data[[#This Row],[Spend]]>0, (campaign_data[[#This Row],[Revenue]]-campaign_data[[#This Row],[Spend]])/campaign_data[[#This Row],[Spend]],0) -> 6.5925362 | R13: =campaign_data[[#This Row],[Revenue]]-campaign_data[[#This Row],[Spend]] -> 8656
... A53: Facebook Engagement | B53: Social | C53: Latin America | D53: 45572 | E53: 45605 | F53: 1976 | G53: 44094 | H53: 2324 | I53: 296 | J53: 24 | K53: 8749 | L53: =campaign_data[[#This Row],[Clicks]]/campaign_data[[#This Row],[Impressions]] -> 0.052705584 | M53: =campaign_data[[#This Row],[Leads]]/campaign_data[[#This Row],[Clicks]] -> 0.12736661 | N53: =campaign_data[[#This Row],[Conversions]]/campaign_data[[#This Row],[Leads]] -> 0.081081081 | O53: =campaign_data[[#This Row],[Spend]]/campaign_data[[#This Row],[Leads]] -> 6.6756757 | P53: =IF(campaign_data[[#This Row],[Conversions]] > 0, campaign_data[[#This Row],[Spend]]/campaign_data[[#This Row],[Conversions]], 0) -> 82.333333 | Q53: =IF(campaign_data[[#This Row],[Spend]]>0, (campaign_data[[#This Row],[Revenue]]-campaign_data[[#This Row],[Spend]])/campaign_data[[#This Row],[Spend]],0) -> 3.4276316 | R53: =campaign_data[[#This Row],[Revenue]]-campaign_data[[#This Row],[Spend]] -> 6773

Sheet Analysis
A1: CHANNEL PERFORMANCE
A2: Business Question: What region should we invest more in ?
A4: Row Labels | B4: Sum of Revenue | C4: Sum of Spend | D4: Average of ROI % (Return on Investment)
A5: Referral | B5: 77281 | C5: 2783 | D5: 31.039549
A6: Paid Ads | B6: 156485 | C6: 75827 | D6: 1.8540679
A7: Email | B7: 159506 | C7: 14814 | D7: 11.350413
A8: Social | B8: 336680 | C8: 82545 | D8: 3.4484066
A9: Grand Total | B9: 729952 | C9: 175969 | D9: 6.8744561
A12: TOP CAMPAIGNS BY ROI
A13: Business Question:Which specific campaigns should we scale? Which should we kill?
A15: Row Labels | B15: Average of ROI % (Return on Investment)
A16: Email Re-engagement | B16: 16.326113
A17: Referral Bonus | B17: 27.771804
A18: Affiliate Marketing | B18: 28.140873
A19: Email Newsletter | B19: 34.397678
A20: Affiliate Network | B20: 61.331325
A21: Grand Total | B21: 33.593559
A24: Bottom 5
A25: Row Labels | B25: Average of ROI % (Return on Investment)
A26: Google Ads - Local | B26: -0.92124504
A27: Instagram Shopping | B27: -0.3723254
A28: Pinterest Promoted | B28: -0.3355467
A29: Native Ads | B29: -0.0085095733
A30: Fall Campaign Social | B30: 0.11718593
A31: Grand Total | B31: -0.30408816
A42: What are rhe Regionwise returns?
A44: Row Labels | B44: Average of ROI % (Return on Investment)
A45: Europe | B45: 10.194365
A46: North America | B46: 6.422265
A47: Asia Pacific | B47: 6.3934005
A48: Latin America | B48: 4.4877938
A49: Grand Total | B49: 6.8744561
A60: Which channel should we invest more in a Region?
A62: Row Labels | B62: Sum of Conversions
A63: Europe | B63: 806
A64: Social | B64: 430
A65: Paid Ads | B65: 212
A66: Referral | B66: 164
A67: North America | B67: 557
A68: Email | B68: 192
...

Sheet Dashboard
A1: MARKETING CAMPAIGN DASHBOARD
B2: Total Spend | D2: Total Revenue | F2: Total Profit | H2: Overall ROI | J2: Total Conversions | L2: Cost Per Acquisition (CPA | N2: Referral has the Highest ROI
B3: =SUM('campaign_data'!F2:'campaign_data'!F53) -> 175969 | D3: =SUM('campaign_data'!K2:'campaign_data'!K53) -> 729952 | F3: =SUM('campaign_data'!R2:'campaign_data'!R53) -> 553983 | H3: =(D3-B3)/B3 -> 3.1481852 | J3: =SUM('campaign_data'!J2:'campaign_data'!J53) -> 2264 | L3: =Dashboard!B3/Dashboard!J3 -> 77.724823 | N3: 31.O4X
B41: KEY FINDINGS FOR MARKETING DASHBOARD:
B43: 1. Referral & Email are ROI Powerhouses: Referral (Avg. 31.0x ROI) and Email (Avg. 11.4x ROI) are the most efficient channels. The "Affiliate Network" campaign is the standout performer with a massive 61.3x ROI.
B44: 2. Social Drives Volume but Lacks Efficiency: While Social generates the highest total revenue ($336,680), its average ROI (3.45x) is significantly lower than Email. Some campaigns, like "Pinterest Promoted," are currently yielding negative returns.
B45: 3. Critical Efficiency Gap in Paid Ads: Paid Ads is the lowest-performing channel (1.85x Avg. ROI). Specifically, "Google Ads - Local" is the worst-performing campaign across the board with a -92% ROI.
B46: 4. Major Funnel Bottleneck: There is a significant 90% drop-off from Leads to Conversions. While the team is successful at generating leads (23,825), the conversion to actual sales (2,264) is a critical friction point.
B47: 5. Regional Performance Variance: Europe is the most efficient region (Avg. 10.2x ROI), significantly outperforming Latin America (4.5x), suggesting that current strategies are resonating better with European audiences.
B48: 6. Low-cost "Trust" channels like Referral and Email are outperforming Paid Ads in every region, headlined by the European Affiliate Network which delivers a massive $61\times$ return on investment.
B50: STRATEGIC RECOMMENDATIONS:
B51: STRATEGIC RECOMMENDATIONS:
B52: 1. Pivot Spend to High-Efficiency Channels: Reallocate 20–30% of the underperforming Paid Ads and Social budgets toward Referral (Affiliate) and Email campaigns to maximize overall profitability.
B53: 2.Scale the Affiliate Model: The "Affiliate Network" campaign is a standout success with a 61.3% ROI. You should investigate scaling this partnership or replicating the model with new partners.
B54: 3. Scale the "Europe" Model: Analyze the specific messaging and offers used in Europe to determine if they can be adapted for the Asia Pacific and Latin America markets to improve regional ROI.
... B63: ⚡ WEEK 4: Regional Pilot: Launch a "Best of Europe" creative test in the Latin America region to see if proven European assets can boost the lower regional performance.
